(0.003) SELECT "auth_user"."id", "auth_user"."password", "auth_user"."last_login", "auth_user"."is_superuser", "auth_user"."username", "auth_user"."first_name", "auth_user"."last_name", "auth_user"."email", "auth_user"."is_staff", "auth_user"."is_active", "auth_user"."date_joined" FROM "auth_user" WHERE "auth_user"."username" = 'seba' LIMIT 21; args=('seba',); alias=default
(0.001) SELECT "Usuarios"."id", "Usuarios"."tipo_usuario_id", "Usuarios"."usuario", "Usuarios"."contrasena" FROM "Usuarios" WHERE "Usuarios"."usuario" = 'seba' LIMIT 21; args=('seba',); alias=default
Exception while resolving variable 'error' in template 'login.html'.
Traceback (most recent call last):
  File "/home/gym/venv/lib/python3.12/site-packages/django/template/base.py", line 883, in _resolve_lookup
    current = current[bit]
              ~~~~~~~^^^^^
  File "/home/gym/venv/lib/python3.12/site-packages/django/template/context.py", line 85, in __getitem__
    raise KeyError(key)
KeyError: 'error'

During handling of the above exception, another exception occurred:

Traceback (most recent call last):
  File "/home/gym/venv/lib/python3.12/site-packages/django/template/base.py", line 889, in _resolve_lookup
    if isinstance(current, BaseContext) and getattr(
                                            ^^^^^^^^
AttributeError: type object 'RequestContext' has no attribute 'error'

During handling of the above exception, another exception occurred:

Traceback (most recent call last):
  File "/home/gym/venv/lib/python3.12/site-packages/django/template/base.py", line 899, in _resolve_lookup
    current = current[int(bit)]
                      ^^^^^^^^
ValueError: invalid literal for int() with base 10: 'error'

During handling of the above exception, another exception occurred:

Traceback (most recent call last):
  File "/home/gym/venv/lib/python3.12/site-packages/django/template/base.py", line 906, in _resolve_lookup
    raise VariableDoesNotExist(
django.template.base.VariableDoesNotExist: Failed lookup for key [error] in [{'True': True, 'False': False, 'None': None}, {'csrf_token': <SimpleLazyObject: <function csrf.<locals>._get_val at 0x723de83184a0>>, 'request': <WSGIRequest: GET '/login/'>, 'user': <SimpleLazyObject: <function AuthenticationMiddleware.process_request.<locals>.<lambda> at 0x723de85b0680>>, 'perms': PermWrapper(<SimpleLazyObject: <function AuthenticationMiddleware.process_request.<locals>.<lambda> at 0x723de85b0680>>), 'messages': <FallbackStorage: request=<WSGIRequest: GET '/login/'>>, 'DEFAULT_MESSAGE_LEVELS': {'DEBUG': 10, 'INFO': 20, 'SUCCESS': 25, 'WARNING': 30, 'ERROR': 40}}, {}, {'form': <LoginForm bound=False, valid=Unknown, fields=(usuario;contrasena)>}, {'block': <Block Node: content. Contents: [<TextNode: '\n<!DOCTYPE html>\n<html>\n<'>, StaticNode(varname=None, path=<FilterExpression "'img/ring.jpeg'">), <TextNode: '");\n            backgroun'>, <IfNode>, <TextNode: '\n                        '>, <django.template.defaulttags.CsrfTokenNode object at 0x723de831dcd0>, <TextNode: '\n                        '>, <URLNode view_name=''password_reset_request'' args=[] kwargs={} as=None>, <TextNode: '">Recuperar Contraseña</a'>]>}]
Exception while resolving variable 'error' in template 'login.html'.
Traceback (most recent call last):
  File "/home/gym/venv/lib/python3.12/site-packages/django/template/base.py", line 883, in _resolve_lookup
    current = current[bit]
              ~~~~~~~^^^^^
  File "/home/gym/venv/lib/python3.12/site-packages/django/template/context.py", line 85, in __getitem__
    raise KeyError(key)
KeyError: 'error'

During handling of the above exception, another exception occurred:

Traceback (most recent call last):
  File "/home/gym/venv/lib/python3.12/site-packages/django/template/base.py", line 889, in _resolve_lookup
    if isinstance(current, BaseContext) and getattr(
                                            ^^^^^^^^
AttributeError: type object 'RequestContext' has no attribute 'error'

During handling of the above exception, another exception occurred:

Traceback (most recent call last):
  File "/home/gym/venv/lib/python3.12/site-packages/django/template/base.py", line 899, in _resolve_lookup
    current = current[int(bit)]
                      ^^^^^^^^
ValueError: invalid literal for int() with base 10: 'error'

During handling of the above exception, another exception occurred:

Traceback (most recent call last):
  File "/home/gym/venv/lib/python3.12/site-packages/django/template/base.py", line 906, in _resolve_lookup
    raise VariableDoesNotExist(
django.template.base.VariableDoesNotExist: Failed lookup for key [error] in [{'True': True, 'False': False, 'None': None}, {'csrf_token': <SimpleLazyObject: <function csrf.<locals>._get_val at 0x723de8318860>>, 'request': <WSGIRequest: POST '/login/'>, 'user': <SimpleLazyObject: <function AuthenticationMiddleware.process_request.<locals>.<lambda> at 0x723de85b0a40>>, 'perms': PermWrapper(<SimpleLazyObject: <function AuthenticationMiddleware.process_request.<locals>.<lambda> at 0x723de85b0a40>>), 'messages': <FallbackStorage: request=<WSGIRequest: POST '/login/'>>, 'DEFAULT_MESSAGE_LEVELS': {'DEBUG': 10, 'INFO': 20, 'SUCCESS': 25, 'WARNING': 30, 'ERROR': 40}}, {}, {'form': <LoginForm bound=True, valid=False, fields=(usuario;contrasena)>}, {'block': <Block Node: content. Contents: [<TextNode: '\n<!DOCTYPE html>\n<html>\n<'>, StaticNode(varname=None, path=<FilterExpression "'img/ring.jpeg'">), <TextNode: '");\n            backgroun'>, <IfNode>, <TextNode: '\n                        '>, <django.template.defaulttags.CsrfTokenNode object at 0x723de831d040>, <TextNode: '\n                        '>, <URLNode view_name=''password_reset_request'' args=[] kwargs={} as=None>, <TextNode: '">Recuperar Contraseña</a'>]>}]
